<?xml version="1.0"?>

<robot name="flappy_sjtu">

	<link name="base_link">
		<inertial>
			<origin xyz="0.0 0.0 0.0" rpy="0.0 0.0 0.0"/>
			<mass value="14.64E-3"/>
			<inertia ixx="11.585E-6" ixy="0.0" ixz="0.0" iyy="8.889E-6" iyz="0.0" izz="3.580E-6"/>
		</inertial>
		<visual>
			<origin xyz="1.286E-3 -0.551E-3 -8.089E-3" rpy="0.0 0.0 0.0"/>
			<geometry>
				<mesh filename = "package://rviz_teleop_commander/meshes/torso.STL"/>
			</geometry>
			<material name="flappy_main">
				<color rgba="0.710 0.392 0.2 1.0"/>
			</material>
		</visual>
	</link>
  
	<link name="flapping_mechanism">
		<inertial>
			<origin xyz="-2.979E-3 0.006E-3 4.928E-3" rpy="0.0 0.0 0.0"/>
			<mass value="8.83E-3"/>
			<inertia ixx="1.256E-6" ixy="0.0" ixz="-0.086E-6" iyy="1.037E-6" iyz="0.0" izz="0.482E-6"/>
		</inertial>
		<visual>
			<origin xyz="0.0 0.0 0.0" rpy="0.0 0.0 0.0"/>
			<geometry>
				<mesh filename = "package://rviz_teleop_commander/meshes/flapping_mechanism.STL"/>
			</geometry>
			<material name="flappy_top">
				<color rgba="0.6 0.6 0.6 1.0"/>
			</material>
		</visual>
	</link>
    
  	<link name = "left_wing">
		<inertial>
			<origin xyz = "0.0024E-3 37.3242E-3 -9.8917E-3" rpy = "0 0 0"/>
			<mass value = "0.0626E-3"/>
			<inertia
				ixx = "21.4402E-9"
				iyy = "2.2204E-9"
				izz = "19.2209E-9"
				ixy = "-0.0000E-9"
				iyz = "0.1968E-9"
				ixz = "-0.0001E-9"/>
		</inertial>
		<visual>
			<origin xyz = "0 0 0" rpy = "0 0 0"/>
			<geometry>
				<mesh filename = "package://rviz_teleop_commander/meshes/Wing_Camber_70mm_C35mm_no_trailing_L.STL"/>
			</geometry>
      <material name="flappy_blue">
          <color rgba="1.0 0.949 0.875 1.0"/>
      </material>
		</visual>
	</link>

	<link name = "right_wing">
		<inertial>
			<origin xyz = "-0.0024E-3 -37.3242E-3 -9.8917E-3" rpy = "0 0 0"/>
			<mass value = "0.0626E-3"/>
			<inertia
				ixx = "21.4402E-9"
				iyy = "2.2204E-9"
				izz = "19.2209E-9"
				ixy = "-0.0000E-9"
				iyz = "-0.1968E-9"
				ixz = "0.0001E-9"/>
		</inertial>
		<visual>
			<origin xyz = "0 0 0" rpy = "0 0 0"/>
			<geometry>
				<mesh filename = "package://rviz_teleop_commander/meshes/right_wing.STL"/>
			</geometry>
			<material name="flappy_red">
          <color rgba="0.788 0.216 0.337 1.0"/>
      </material>
		</visual>
	</link>

	<link name="left_leading_edge">
		<inertial>
			<origin xyz = "-0.2837E-3 3.3023E-3 -6.3984E-3" rpy = "0 0 0"/>
			<mass value = "0.7081E-3"/>
			<inertia
				ixx = "132.8411E-9"
				iyy = "47.7258E-9"
				izz = "90.6904E-9"
				ixy = "-0.0416E-9"
				iyz = "12.5149E-9"
				ixz = "-0.4990E-9"/>
		</inertial>
		<visual>
			<origin xyz = "0 0 0" rpy = "0 0 0"/>
			<geometry>
				<mesh filename = "package://rviz_teleop_commander/meshes/left_LE.STL"/>
			</geometry>
			<material name="flappy_blue">
          <color rgba="0.0 0.0 1.0 1.0"/>
      </material>
		</visual>
	</link>

	<link name="right_leading_edge">
		<inertial>
			<origin xyz = "-0.2837E-3 -3.3023E-3 -6.3984E-3" rpy = "0 0 0"/>
			<mass value = "0.7081E-3"/>
			<inertia
				ixx = "132.8411E-9"
				iyy = "47.7258E-9"
				izz = "90.6904E-9"
				ixy = "0.0416E-9"
				iyz = "-12.5149E-9"
				ixz = "-0.4990E-9"/>
		</inertial>
		<visual>
			<origin xyz = "0 0 0" rpy = "0 0 0"/>
			<geometry>
				<mesh filename = "package://rviz_teleop_commander/meshes/right_LE.STL"/>
			</geometry>
			<material name="flappy_red">
          <color rgba="1.0 0.0 0.0 1.0"/>
      </material>
		</visual>
	</link>
    
	<joint name="servo_control" type="revolute">
		<origin xyz="1.286E-3 -0.551E-3 41.911E-3" rpy="0.0 0.0 0.0"/>
		<parent link="base_link"/>
		<child link="flapping_mechanism"/>
		<axis xyz="0.0 1.0 0.0"/>
		<limit lower="-0.5" upper="0.5" effort="0.02" velocity="400.0"/>
	</joint>
    
	<joint name = "left_stroke" type = "revolute">
		<parent link = "flapping_mechanism"/>
		<child link = "left_leading_edge"/>
		<origin xyz = "0 13.95E-3 18.9913E-3" rpy = "0 0 0"/>
		<axis xyz = "0 0 1"/>
		<dynamics friction = "1E-9" damping = "8E-9"/>
		<limit lower = "-1.63" upper = "1.63" effort = "0.02" velocity = "400"/>
	</joint>

	<joint name = "left_rotate" type = "revolute">
		<parent link = "left_leading_edge"/>
		<child link = "left_wing"/>
		<origin xyz = "0 0 0" rpy = "0 0 0"/>
		<axis xyz = "0 1 0"/>
		<dynamics friction = "1E-8" damping = "1E-9"/>
		<limit lower = "-0.7854" upper = "0.7854" effort = "0.02" velocity = "2000"/>
	</joint>

	<joint name = "right_stroke" type = "revolute">
		<parent link = "flapping_mechanism"/>
		<child link = "right_leading_edge"/>
		<origin xyz = "0 -13.95E-3 18.9913E-3" rpy = "0 0 0"/>
		<axis xyz = "0 0 -1"/>
		<dynamics friction = "1E-9" damping = "8E-9"/>
		<limit lower = "-1.63" upper = "1.63" effort = "0.02" velocity = "400"/>
	</joint>

	<joint name = "right_rotate" type = "revolute">
		<parent link = "right_leading_edge"/>
		<child link = "right_wing"/>
		<origin xyz = "0 0 0" rpy = "0 0 0"/>
		<axis xyz = "0 1 0"/>
		<dynamics friction = "1E-8" damping = "1E-9"/>
		<limit lower = "-0.7854" upper = "0.7854" effort = "0.02" velocity = "2000"/>
	</joint>

</robot>